#VRML_SIM R2023b utf8

EXTERNPROTO "https://raw.githubusercontent.com/cyberbotics/webots/R2023b/projects/objects/backgrounds/protos/TexturedBackground.proto"
EXTERNPROTO "https://raw.githubusercontent.com/cyberbotics/webots/R2023b/projects/objects/backgrounds/protos/TexturedBackgroundLight.proto"
EXTERNPROTO "https://raw.githubusercontent.com/cyberbotics/webots/R2023b/projects/objects/floors/protos/Floor.proto"
EXTERNPROTO "https://raw.githubusercontent.com/cyberbotics/webots/R2023b/projects/devices/robotiq/protos/Robotiq2f140Gripper.proto"

WorldInfo {
}
Viewpoint {
  orientation 0.2172299071686083 0.11603463973960301 -0.9691992209097251 2.095483538499549
  position 2.9119769275471366 3.6854206326473924 2.1691971428305754
}
TexturedBackground {
}
TexturedBackgroundLight {
}
Floor {
  rotation 0 0 1 -0.5235996938995747
}
Robot {
  translation 0 0 0.43
  children [
    DEF Body Solid {
      children [
        HingeJoint {
          jointParameters DEF Hinge1 HingeJointParameters {
            axis 0 0 1
          }
          device [
            RotationalMotor {
              name "hinge1"
            }
          ]
          endPoint Solid {
            translation 0.167882 -0.0967765 0.49
            rotation 0.24816044788771616 0.9363937602987158 -0.24815946038343883 1.6364722483946137
            children [
              HingeJoint {
                jointParameters HingeJointParameters {
                  anchor 0 0 0.2
                }
                device [
                  RotationalMotor {
                    name "hinge2"
                  }
                ]
                endPoint Solid {
                  translation -0.050001799999999985 -1e-07 0.43
                  rotation -2.6513645595158955e-05 -0.9999999996485114 -6.240504504975437e-08 5.307073192177323e-06
                  children [
                    DEF Arm2 Shape {
                      appearance PBRAppearance {
                        baseColor 0 0 1
                      }
                      geometry Cylinder {
                        height 0.5
                        radius 0.05
                      }
                    }
                    SliderJoint {
                      jointParameters JointParameters {
                        position 0.2
                        axis 1 0 0
                      }
                      device [
                        LinearMotor {
                          name "slider"
                          acceleration 1
                        }
                      ]
                      endPoint Solid {
                        translation -0.21 0 0.17
                        rotation 0 1 0 -1.5707953071795862
                        children [
                          Robotiq2f140Gripper {
                            translation 6.41399e-06 2.47701e-05 -0.33
                            rotation 6.126567591314212e-07 0.999999999995141 3.0566009750399888e-06 3.1415887394615924
                          }
                          DEF UpDown Shape {
                            appearance PBRAppearance {
                              baseColor 0 0 1
                              roughness 1
                            }
                            geometry Cylinder {
                              height 0.75
                              radius 0.02
                            }
                          }
                        ]
                        name "solid(3)"
                        boundingObject USE UpDown
                      }
                    }
                  ]
                  name "solid(2)"
                  boundingObject USE Arm2
                }
              }
              DEF Arm1 Shape {
                appearance PBRAppearance {
                  baseColor 0 0 1
                }
                geometry Cylinder {
                  height 0.5
                  radius 0.05
                }
              }
            ]
            boundingObject USE Arm1
          }
        }
        DEF Body Shape {
          geometry Cylinder {
            height 1
            radius 0.05
          }
        }
      ]
      name "solid(3)"
    }
  ]
  boundingObject USE Body
  rotationStep 0.261785
  controller "my_robot_controller"
}
